<?xml version="1.0"?>
<robot name="robot2" xmlns:xacro="http://ros.org/wiki/xacro">

  <!-- Colors -->
  <material name="grey"><color rgba="0.5 0.5 0.5 1"/></material>
  <material name="white"><color rgba="1 1 1 1"/></material>
  <material name="green"><color rgba="0 0.5 0 1"/></material>

  <!-- Base footprint -->
  <link name="base_footprint"/>

  <!-- Base -->
  <link name="base_link">
    <visual>
      <geometry><box size="0.6 0.4 0.2"/></geometry>
      <origin xyz="0 0 0.1"/>
      <material name="green"/>
    </visual>
    <collision>
      <geometry><box size="0.6 0.4 0.2"/></geometry>
      <origin xyz="0 0 0.1"/>
    </collision>
    <inertial>
      <mass value="5"/>
      <origin xyz="0 0 0.1"/>
      <inertia ixx="0.02" ixy="0.0" ixz="0.0" iyy="0.02" iyz="0.0" izz="0.02"/>
    </inertial>
  </link>

  <!-- Fixed joint to base_footprint -->
  <joint name="base_joint" type="fixed">
    <parent link="base_footprint"/>
    <child link="base_link"/>
    <origin xyz="0 0 0"/>
  </joint>

  <!-- Lidar -->
  <link name="lidar">
    <visual>
      <geometry><cylinder radius="0.05" length="0.05"/></geometry>
      <origin xyz="0 0 0" rpy="0 0 0"/>
      <material name="white"/>
    </visual>
  </link>

  <joint name="lidar_joint" type="fixed">
    <parent link="base_link"/>
    <child link="lidar"/>
    <origin xyz="0 0 0.225"/>
  </joint>

  <!-- Wheels: Left and Right Back (Movable) -->
  <link name="left_back_wheel">
    <visual>
      <geometry><cylinder radius="0.1" length="0.05"/></geometry>
      <origin xyz="0 0 -0.05" rpy="1.57 0 0"/>
      <material name="grey"/>
    </visual>
    <collision>
      <geometry><cylinder radius="0.1" length="0.05"/></geometry>
      <origin xyz="0 0 -0.05" rpy="1.57 0 0"/>
    </collision>
    <inertial>
      <mass value="0.5"/>
      <origin xyz="0 0 -0.05"/>
      <inertia ixx="0.001" ixy="0.0" ixz="0.0" iyy="0.001" iyz="0.0" izz="0.001"/>
    </inertial>
  </link>

  <link name="right_back_wheel">
    <visual>
      <geometry><cylinder radius="0.1" length="0.05"/></geometry>
      <origin xyz="0 0 -0.05" rpy="1.57 0 0"/>
      <material name="grey"/>
    </visual>
    <collision>
      <geometry><cylinder radius="0.1" length="0.05"/></geometry>
      <origin xyz="0 0 -0.05" rpy="1.57 0 0"/>
    </collision>
    <inertial>
      <mass value="0.5"/>
      <origin xyz="0 0 -0.05"/>
      <inertia ixx="0.001" ixy="0.0" ixz="0.0" iyy="0.001" iyz="0.0" izz="0.001"/>
    </inertial>
  </link>

  <joint name="left_back_wheel_joint" type="continuous">
    <parent link="base_link"/>
    <child link="left_back_wheel"/>
    <origin xyz="-0.15 0.225 0"/>
    <axis xyz="0 1 0"/>
  </joint>

  <joint name="right_back_wheel_joint" type="continuous">
    <parent link="base_link"/>
    <child link="right_back_wheel"/>
    <origin xyz="-0.15 -0.225 0"/>
    <axis xyz="0 1 0"/>
  </joint>

  <!-- Decorative Front Wheels (Fixed) -->
  <link name="left_front_wheel">
    <visual>
      <geometry><cylinder radius="0.1" length="0.05"/></geometry>
      <origin xyz="0 0 -0.05" rpy="1.57 0 0"/>
      <material name="grey"/>
    </visual>
  </link>

  <link name="right_front_wheel">
    <visual>
      <geometry><cylinder radius="0.1" length="0.05"/></geometry>
      <origin xyz="0 0 -0.05" rpy="1.57 0 0"/>
      <material name="grey"/>
    </visual>
  </link>

  <joint name="left_front_wheel_joint" type="fixed">
    <parent link="base_link"/>
    <child link="left_front_wheel"/>
    <origin xyz="0.15 0.225 0"/>
  </joint>

  <joint name="right_front_wheel_joint" type="fixed">
    <parent link="base_link"/>
    <child link="right_front_wheel"/>
    <origin xyz="0.15 -0.225 0"/>
  </joint>

  <!-- Transmissions -->
  <transmission name="left_back_trans">
    <type>transmission_interface/SimpleTransmission</type>
    <joint name="left_back_wheel_joint">
      <hardwareInterface>hardware_interface/VelocityJointInterface</hardwareInterface>
    </joint>
    <actuator name="left_motor">
      <hardwareInterface>hardware_interface/VelocityJointInterface</hardwareInterface>
      <mechanicalReduction>1</mechanicalReduction>
    </actuator>
  </transmission>

  <transmission name="right_back_trans">
    <type>transmission_interface/SimpleTransmission</type>
    <joint name="right_back_wheel_joint">
      <hardwareInterface>hardware_interface/VelocityJointInterface</hardwareInterface>
    </joint>
    <actuator name="right_motor">
      <hardwareInterface>hardware_interface/VelocityJointInterface</hardwareInterface>
      <mechanicalReduction>1</mechanicalReduction>
    </actuator>
  </transmission>

  <!-- Gazebo ROS2 Control -->
  <gazebo>
    <plugin name="gazebo_ros_control" filename="libgazebo_ros2_control.so"/>
  </gazebo>

  <!-- Diff Drive Plugin -->
  <gazebo>
    <plugin name="diff_drive_controller_robot2" filename="libgazebo_ros_diff_drive.so">
      <ros>
        <remapping>cmd_vel:=/robot2/cmd_vel</remapping>
        <remapping>odom:=/robot2/odom</remapping>
      </ros>
      <left_joint>left_back_wheel_joint</left_joint>
      <right_joint>right_back_wheel_joint</right_joint>
      <wheelSeparation>0.45</wheelSeparation>
      <wheelDiameter>0.2</wheelDiameter>
      <torque>5.0</torque>
      <commandTopic>/robot2/cmd_vel</commandTopic>
      <odometryTopic>/robot2/odom</odometryTopic>
      <robotBaseFrame>base_link</robotBaseFrame>
    </plugin>
  </gazebo>

  <!-- Wheel friction -->
  <gazebo reference="left_back_wheel"><mu1>1.0</mu1><mu2>1.0</mu2></gazebo>
  <gazebo reference="right_back_wheel"><mu1>1.0</mu1><mu2>1.0</mu2></gazebo>

</robot>
