<?xml version="1.0"?>
<robot name="robot2" xmlns:xacro="http://www.ros.org/wiki/xacro">

  <!-- Base Link -->
  <link name="base_link">
    <visual>
      <geometry>
        <box size="0.4 0.3 0.2"/>
      </geometry>
      <material name="blue">
        <color rgba="0 0 1 1"/>
      </material>
    </visual>
    <collision>
      <geometry>
        <box size="0.4 0.3 0.2"/>
      </geometry>
    </collision>
    <inertial>
      <mass value="5.0"/>
      <origin xyz="0 0 0" />
      <inertia ixx="0.1" ixy="0.0" ixz="0.0"
               iyy="0.1" iyz="0.0"
               izz="0.1"/>
    </inertial>
  </link>

  <!-- Front Left Wheel (decorative) -->
  <link name="front_left_wheel">
    <visual>
      <geometry>
        <cylinder radius="0.05" length="0.02"/>
      </geometry>
      <origin xyz="0 0 0" rpy="1.5708 0 0"/>
      <material name="black"/>
    </visual>
    <collision>
      <geometry>
        <cylinder radius="0.05" length="0.02"/>
      </geometry>
      <origin xyz="0 0 0" rpy="1.5708 0 0"/>
    </collision>
  </link>

  <joint name="front_left_wheel_joint" type="fixed">
    <parent link="base_link"/>
    <child link="front_left_wheel"/>
    <origin xyz="0.15 0.15 -0.1" rpy="0 0 0"/>
  </joint>

  <!-- Front Right Wheel (decorative) -->
  <link name="front_right_wheel">
    <visual>
      <geometry>
        <cylinder radius="0.05" length="0.02"/>
      </geometry>
      <origin xyz="0 0 0" rpy="1.5708 0 0"/>
      <material name="black"/>
    </visual>
    <collision>
      <geometry>
        <cylinder radius="0.05" length="0.02"/>
      </geometry>
      <origin xyz="0 0 0" rpy="1.5708 0 0"/>
    </collision>
  </link>

  <joint name="front_right_wheel_joint" type="fixed">
    <parent link="base_link"/>
    <child link="front_right_wheel"/>
    <origin xyz="0.15 -0.15 -0.1" rpy="0 0 0"/>
  </joint>

  <!-- Rear Left Wheel (controlled) -->
  <link name="rear_left_wheel">
    <visual>
      <geometry>
        <cylinder radius="0.05" length="0.02"/>
      </geometry>
      <origin xyz="0 0 0" rpy="1.5708 0 0"/>
      <material name="black"/>
    </visual>
    <collision>
      <geometry>
        <cylinder radius="0.05" length="0.02"/>
      </geometry>
      <origin xyz="0 0 0" rpy="1.5708 0 0"/>
    </collision>
  </link>

  <joint name="rear_left_wheel_joint" type="continuous">
    <parent link="base_link"/>
    <child link="rear_left_wheel"/>
    <origin xyz="-0.15 0.15 -0.1" rpy="0 0 0"/>
    <axis xyz="0 1 0"/>
  </joint>

  <!-- Rear Right Wheel (controlled) -->
  <link name="rear_right_wheel">
    <visual>
      <geometry>
        <cylinder radius="0.05" length="0.02"/>
      </geometry>
      <origin xyz="0 0 0" rpy="1.5708 0 0"/>
      <material name="black"/>
    </visual>
    <collision>
      <geometry>
        <cylinder radius="0.05" length="0.02"/>
      </geometry>
      <origin xyz="0 0 0" rpy="1.5708 0 0"/>
    </collision>
  </link>

  <joint name="rear_right_wheel_joint" type="continuous">
    <parent link="base_link"/>
    <child link="rear_right_wheel"/>
    <origin xyz="-0.15 -0.15 -0.1" rpy="0 0 0"/>
    <axis xyz="0 1 0"/>
  </joint>

  <!-- Caster Wheel -->
  <link name="caster_wheel">
    <visual>
      <geometry>
        <sphere radius="0.03"/>
      </geometry>
      <material name="gray"/>
    </visual>
    <collision>
      <geometry>
        <sphere radius="0.03"/>
      </geometry>
    </collision>
  </link>

  <joint name="caster_joint" type="fixed">
    <parent link="base_link"/>
    <child link="caster_wheel"/>
    <origin xyz="0.15 0 -0.12" rpy="0 0 0"/>
  </joint>

  <!-- Gazebo Plugin for Differential Drive -->
  <gazebo>
    <plugin name="diff_drive_controller_robot2" filename="libgazebo_ros_diff_drive.so">
      <ros>
        <namespace>/robot2</namespace>
      </ros>
      <left_joint>rear_left_wheel_joint</left_joint>
      <right_joint>rear_right_wheel_joint</right_joint>
      <wheel_separation>0.3</wheel_separation>
      <wheel_diameter>0.1</wheel_diameter>
      <publish_odom>true</publish_odom>
      <odom_topic>odom</odom_topic>
      <cmd_vel_topic>cmd_vel</cmd_vel_topic>
    </plugin>
  </gazebo>

</robot>
